<?xml version="1.0"?>
<robot name="decode_robot">
  <!-- Materials -->
  <material name="gray"><color rgba="0.5 0.5 0.5 1"/></material>
  <material name="black"><color rgba="0 0 0 1"/></material>
  <material name="green"><color rgba="0 1 0 1"/></material>
  <material name="blue"><color rgba="0 0 1 1"/></material>
  <material name="red"><color rgba="1 0 0 1"/></material>
  <material name="yellow"><color rgba="1 1 0 1"/></material>
  <material name="white"><color rgba="1 1 1 1"/></material>

  <!-- Base Link -->
  <link name="base_link">
    <visual>
      <geometry><box size="0.4 0.4 0.05"/></geometry>
      <material name="gray"/>
    </visual>
    <collision>
      <geometry><box size="0.4 0.4 0.05"/></geometry>
    </collision>
    <inertial>
      <mass value="10.0"/>
      <inertia ixx="0.1" ixy="0" ixz="0" iyy="0.1" iyz="0" izz="0.1"/>
    </inertial>
  </link>

  <!-- Wheels (Standard Cylinders for now) -->
  <link name="fl_wheel">
    <visual>
      <geometry><cylinder length="0.05" radius="0.05"/></geometry>
      <material name="black"/>
    </visual>
    <collision>
      <geometry><cylinder length="0.05" radius="0.05"/></geometry>
      <!-- Friction properties would be set in a separate tag in SDF/Drake custom tags, using standard here -->
    </collision>
    <inertial>
      <mass value="0.5"/>
      <inertia ixx="0.001" ixy="0" ixz="0" iyy="0.001" iyz="0" izz="0.001"/>
    </inertial>
  </link>
  <joint name="fl_wheel_joint" type="continuous">
    <parent link="base_link"/>
    <child link="fl_wheel"/>
    <origin xyz="0.15 0.15 0" rpy="-1.5708 0 0"/>
    <axis xyz="0 0 1"/>
  </joint>

  <link name="fr_wheel">
    <visual>
      <geometry><cylinder length="0.05" radius="0.05"/></geometry>
      <material name="black"/>
    </visual>
    <collision>
      <geometry><cylinder length="0.05" radius="0.05"/></geometry>
    </collision>
    <inertial>
      <mass value="0.5"/>
      <inertia ixx="0.001" ixy="0" ixz="0" iyy="0.001" iyz="0" izz="0.001"/>
    </inertial>
  </link>
  <joint name="fr_wheel_joint" type="continuous">
    <parent link="base_link"/>
    <child link="fr_wheel"/>
    <origin xyz="0.15 -0.15 0" rpy="-1.5708 0 0"/>
    <axis xyz="0 0 1"/>
  </joint>

  <link name="bl_wheel">
    <visual>
      <geometry><cylinder length="0.05" radius="0.05"/></geometry>
      <material name="black"/>
    </visual>
    <collision>
      <geometry><cylinder length="0.05" radius="0.05"/></geometry>
    </collision>
    <inertial>
      <mass value="0.5"/>
      <inertia ixx="0.001" ixy="0" ixz="0" iyy="0.001" iyz="0" izz="0.001"/>
    </inertial>
  </link>
  <joint name="bl_wheel_joint" type="continuous">
    <parent link="base_link"/>
    <child link="bl_wheel"/>
    <origin xyz="-0.15 0.15 0" rpy="-1.5708 0 0"/>
    <axis xyz="0 0 1"/>
  </joint>

  <link name="br_wheel">
    <visual>
      <geometry><cylinder length="0.05" radius="0.05"/></geometry>
      <material name="black"/>
    </visual>
    <collision>
      <geometry><cylinder length="0.05" radius="0.05"/></geometry>
    </collision>
    <inertial>
      <mass value="0.5"/>
      <inertia ixx="0.001" ixy="0" ixz="0" iyy="0.001" iyz="0" izz="0.001"/>
    </inertial>
  </link>
  <joint name="br_wheel_joint" type="continuous">
    <parent link="base_link"/>
    <child link="br_wheel"/>
    <origin xyz="-0.15 -0.15 0" rpy="-1.5708 0 0"/>
    <axis xyz="0 0 1"/>
  </joint>

  <!-- Intake Roller -->
  <link name="intake_link">
    <visual>
      <geometry><cylinder length="0.3" radius="0.03"/></geometry>
      <material name="green"/>
    </visual>
    <collision>
      <geometry><cylinder length="0.3" radius="0.03"/></geometry>
    </collision>
    <inertial>
      <mass value="0.2"/>
      <inertia ixx="0.001" ixy="0" ixz="0" iyy="0.001" iyz="0" izz="0.001"/>
    </inertial>
  </link>
  <joint name="intake_joint" type="continuous">
    <parent link="base_link"/>
    <child link="intake_link"/>
    <origin xyz="0.25 0 0" rpy="0 1.5708 0"/>
    <axis xyz="0 0 1"/>
  </joint>

  <!-- Spindexer (Rotating platform with dividers) -->
  <link name="spindexer_base_link">
    <visual>
      <geometry><cylinder length="0.01" radius="0.15"/></geometry>
      <material name="blue"/>
    </visual>
    <collision>
      <geometry><cylinder length="0.01" radius="0.15"/></geometry>
    </collision>
    <inertial>
      <mass value="0.5"/>
      <inertia ixx="0.005" ixy="0" ixz="0" iyy="0.005" iyz="0" izz="0.01"/>
    </inertial>
  </link>
  <joint name="spindexer_joint" type="continuous">
    <parent link="base_link"/>
    <child link="spindexer_base_link"/>
    <origin xyz="0 0 0.03" rpy="0 0 0"/>
    <axis xyz="0 0 1"/>
  </joint>
  
  <!-- Spindexer Dividers (Fixed to base link) -->
  <!-- Divider 1 -->
  <link name="div1">
    <collision><geometry><box size="0.15 0.01 0.05"/></geometry></collision>
    <visual><geometry><box size="0.15 0.01 0.05"/></geometry><material name="blue"/></visual>
    <inertial><mass value="0.1"/><inertia ixx="0.0001" ixy="0" ixz="0" iyy="0.0001" iyz="0" izz="0.0001"/></inertial>
  </link>
  <joint name="div1_joint" type="fixed">
    <parent link="spindexer_base_link"/>
    <child link="div1"/>
    <origin xyz="0.075 0 0.03" rpy="0 0 0"/>
  </joint>
  
  <!-- Divider 2 -->
  <link name="div2">
    <collision><geometry><box size="0.15 0.01 0.05"/></geometry></collision>
    <visual><geometry><box size="0.15 0.01 0.05"/></geometry><material name="blue"/></visual>
    <inertial><mass value="0.1"/><inertia ixx="0.0001" ixy="0" ixz="0" iyy="0.0001" iyz="0" izz="0.0001"/></inertial>
  </link>
  <joint name="div2_joint" type="fixed">
    <parent link="spindexer_base_link"/>
    <child link="div2"/>
    <origin xyz="-0.0375 0.065 0.03" rpy="0 0 2.0944"/>
  </joint>

  <!-- Divider 3 -->
  <link name="div3">
    <collision><geometry><box size="0.15 0.01 0.05"/></geometry></collision>
    <visual><geometry><box size="0.15 0.01 0.05"/></geometry><material name="blue"/></visual>
    <inertial><mass value="0.1"/><inertia ixx="0.0001" ixy="0" ixz="0" iyy="0.0001" iyz="0" izz="0.0001"/></inertial>
  </link>
  <joint name="div3_joint" type="fixed">
    <parent link="spindexer_base_link"/>
    <child link="div3"/>
    <origin xyz="-0.0375 -0.065 0.03" rpy="0 0 -2.0944"/>
  </joint>


  <!-- Turret -->
  <!-- Connected to base_link (or spindexer? usually turret is separate, inside or above spindexer. Description says "Back of spindexer has transfer into turret". Implies turret is separate mechanism.) -->
  <!-- Let's put Turret on base_link, effectively passing through spindexer center or above it. -->
  <link name="turret_link">
    <visual>
      <geometry><box size="0.1 0.1 0.1"/></geometry>
      <material name="red"/>
    </visual>
    <collision>
      <geometry><box size="0.1 0.1 0.1"/></geometry>
    </collision>
    <inertial>
      <mass value="1.0"/>
      <inertia ixx="0.01" ixy="0" ixz="0" iyy="0.01" iyz="0" izz="0.01"/>
    </inertial>
  </link>
  <joint name="turret_joint" type="revolute">
    <parent link="base_link"/>
    <child link="turret_link"/>
    <origin xyz="0 0 0.15" rpy="0 0 0"/>
    <axis xyz="0 0 1"/>
    <limit lower="-1.5708" upper="1.5708" effort="20" velocity="10"/>
  </joint>

  <!-- Flywheel -->
  <link name="flywheel_link">
    <visual>
      <geometry><cylinder length="0.02" radius="0.04"/></geometry>
      <material name="yellow"/>
    </visual>
    <collision>
      <geometry><cylinder length="0.02" radius="0.04"/></geometry>
    </collision>
    <inertial>
      <mass value="0.5"/>
      <inertia ixx="0.0005" ixy="0" ixz="0" iyy="0.0005" iyz="0" izz="0.0005"/>
    </inertial>
  </link>
  <joint name="flywheel_joint" type="continuous">
    <parent link="turret_link"/>
    <child link="flywheel_link"/>
    <origin xyz="0.05 0 0.05" rpy="0 1.5708 0"/>
    <axis xyz="0 0 1"/>
  </joint>

  <!-- Adjustable Hood -->
  <!-- The hood needs to form an arc against the flywheel. -->
  <!-- We'll attach a 'hood_base' to the turret, and the hood_link moves relative to it. -->
  <!-- Hood is represented by 3 segments to approximate curve. -->
  
  <link name="hood_pivot">
     <inertial><mass value="0.01"/><inertia ixx="0" ixy="0" ixz="0" iyy="0" iyz="0" izz="0"/></inertial>
  </link>
  <joint name="hood_joint" type="revolute">
    <parent link="turret_link"/>
    <child link="hood_pivot"/>
    <origin xyz="-0.05 0 0.05" rpy="0 0 0"/>
    <axis xyz="0 1 0"/>
    <limit lower="0" upper="1.2" effort="5" velocity="5"/>
  </joint>

  <!-- Segment 1 -->
  <link name="hood_seg1">
     <visual><geometry><box size="0.01 0.08 0.04"/></geometry><material name="white"/></visual>
     <collision><geometry><box size="0.01 0.08 0.04"/></geometry></collision>
     <inertial><mass value="0.05"/><inertia ixx="0.0001" ixy="0" ixz="0" iyy="0.0001" iyz="0" izz="0.0001"/></inertial>
  </link>
  <joint name="h1" type="fixed">
      <parent link="hood_pivot"/>
      <child link="hood_seg1"/>
      <origin xyz="0 0 0.02" rpy="0 -0.2 0"/>
  </joint>
  
  <!-- Segment 2 -->
  <link name="hood_seg2">
     <visual><geometry><box size="0.01 0.08 0.04"/></geometry><material name="white"/></visual>
     <collision><geometry><box size="0.01 0.08 0.04"/></geometry></collision>
     <inertial><mass value="0.05"/><inertia ixx="0.0001" ixy="0" ixz="0" iyy="0.0001" iyz="0" izz="0.0001"/></inertial>
  </link>
  <joint name="h2" type="fixed">
      <parent link="hood_seg1"/>
      <child link="hood_seg2"/>
      <origin xyz="0 0 0.04" rpy="0 -0.3 0"/>
  </joint>

   <!-- Segment 3 -->
  <link name="hood_seg3">
     <visual><geometry><box size="0.01 0.08 0.04"/></geometry><material name="white"/></visual>
     <collision><geometry><box size="0.01 0.08 0.04"/></geometry></collision>
     <inertial><mass value="0.05"/><inertia ixx="0.0001" ixy="0" ixz="0" iyy="0.0001" iyz="0" izz="0.0001"/></inertial>
  </link>
  <joint name="h3" type="fixed">
      <parent link="hood_seg2"/>
      <child link="hood_seg3"/>
      <origin xyz="0 0 0.04" rpy="0 -0.3 0"/>
  </joint>

  <!-- Transfer Ramp (spindexer to turret feed) -->
  <link name="transfer_ramp">
    <visual>
      <geometry><box size="0.12 0.08 0.02"/></geometry>
      <material name="white"/>
    </visual>
    <collision>
      <geometry><box size="0.12 0.08 0.02"/></geometry>
    </collision>
    <inertial>
      <mass value="0.2"/>
      <inertia ixx="0.0002" ixy="0" ixz="0" iyy="0.0002" iyz="0" izz="0.0002"/>
    </inertial>
  </link>
  <joint name="transfer_ramp_joint" type="fixed">
    <parent link="base_link"/>
    <child link="transfer_ramp"/>
    <origin xyz="-0.10 0 0.08" rpy="0 -0.45 0"/>
  </joint>

</robot>
