<?xml version="1.0"?>
<robot name="decode_robot">
  <!-- Materials -->
  <material name="gray"><color rgba="0.5 0.5 0.5 1"/></material>
  <material name="black"><color rgba="0 0 0 1"/></material>
  <material name="green"><color rgba="0 1 0 1"/></material>
  <material name="blue"><color rgba="0 0 1 1"/></material>
  <material name="red"><color rgba="1 0 0 1"/></material>
  <material name="yellow"><color rgba="1 1 0 1"/></material>
  <material name="white"><color rgba="1 1 1 1"/></material>

  <!-- Base Link -->
  <link name="base_link">
    <visual>
      <origin xyz="0 -0.1575875 0" rpy="0 0 1.57079632679"/>
      <geometry><mesh filename="robotMeshes/robot frame.stl" scale="0.001 0.001 0.001"/></geometry>
      <material name="gray"/>
    </visual>
    <collision>
      <origin xyz="0 0 0.0508" rpy="0 0 1.57079632679"/>
      <geometry><box size="0.4367 0.39557406 0.1016"/></geometry>
    </collision>
    <inertial>
      <mass value="15.0"/>
      <inertia ixx="0.1" ixy="0" ixz="0" iyy="0.1" iyz="0" izz="0.1"/>
    </inertial>
  </link>

  <!-- Wheels (Standard Cylinders for now) -->
  <link name="fl_wheel">
    <visual>
      <origin xyz="0 0 0" rpy="-1.57079632679 3.14159265359 0"/>
      <geometry><mesh filename="robotMeshes/wheel.stl" scale="0.001 0.001 0.001"/></geometry>
      <material name="black"/>
    </visual>
    <collision>
      <geometry><cylinder length="0.048" radius="0.048"/></geometry>
    </collision>
    <inertial>
      <mass value="0.5"/>
      <inertia ixx="0.001" ixy="0" ixz="0" iyy="0.001" iyz="0" izz="0.001"/>
    </inertial>
  </link>
  <joint name="fl_wheel_joint" type="continuous">
    <parent link="base_link"/>
    <child link="fl_wheel"/>
    <origin xyz="0.13278703 0.1538125 0.04" rpy="-1.57079632679 0 0"/>
    <axis xyz="0 0 1"/>
  </joint>

  <link name="fr_wheel">
    <visual>
      <origin xyz="0 0 0" rpy="-1.57079632679 0 0"/>
      <geometry><mesh filename="robotMeshes/wheel.stl" scale="0.001 0.001 0.001"/></geometry>
      <material name="black"/>
    </visual>
    <collision>
      <geometry><cylinder length="0.048" radius="0.048"/></geometry>
    </collision>
    <inertial>
      <mass value="0.5"/>
      <inertia ixx="0.001" ixy="0" ixz="0" iyy="0.001" iyz="0" izz="0.001"/>
    </inertial>
  </link>
  <joint name="fr_wheel_joint" type="continuous">
    <parent link="base_link"/>
    <child link="fr_wheel"/>
    <origin xyz="0.13278703 -0.1538125 0.04" rpy="-1.57079632679 0 0"/>
    <axis xyz="0 0 1"/>
  </joint>

  <link name="bl_wheel">
    <visual>
      <origin xyz="0 0 0" rpy="-1.57079632679 3.14159265359 0"/>
      <geometry><mesh filename="robotMeshes/wheel.stl" scale="0.001 0.001 0.001"/></geometry>
      <material name="black"/>
    </visual>
    <collision>
      <geometry><cylinder length="0.05" radius="0.05"/></geometry>
    </collision>
    <inertial>
      <mass value="0.5"/>
      <inertia ixx="0.001" ixy="0" ixz="0" iyy="0.001" iyz="0" izz="0.001"/>
    </inertial>
  </link>
  <joint name="bl_wheel_joint" type="continuous">
    <parent link="base_link"/>
    <child link="bl_wheel"/>
    <origin xyz="-0.13278703 0.1538125 0.04" rpy="-1.57079632679 0 0"/>
    <axis xyz="0 0 1"/>
  </joint>

  <link name="br_wheel">
    <visual>
      <origin xyz="0 0 0" rpy="-1.57079632679 0 0"/>
      <geometry><mesh filename="robotMeshes/wheel.stl" scale="0.001 0.001 0.001"/></geometry>
      <material name="black"/>
    </visual>
    <collision>
      <geometry><cylinder length="0.05" radius="0.05"/></geometry>
    </collision>
    <inertial>
      <mass value="0.5"/>
      <inertia ixx="0.001" ixy="0" ixz="0" iyy="0.001" iyz="0" izz="0.001"/>
    </inertial>
  </link>
  <joint name="br_wheel_joint" type="continuous">
    <parent link="base_link"/>
    <child link="br_wheel"/>
    <origin xyz="-0.13278703 -0.1538125 0.04" rpy="-1.57079632679 0 0"/>
    <axis xyz="0 0 1"/>
  </joint>

  <!-- Intake Roller -->
  <link name="intake_link">
    <visual>
      <geometry><cylinder length="0.2" radius="0.03"/></geometry>
      <material name="green"/>
    </visual>
    <collision>
      <geometry><cylinder length="0.3" radius="0.03"/></geometry>
    </collision>
    <inertial>
      <mass value="0.2"/>
      <inertia ixx="0.001" ixy="0" ixz="0" iyy="0.001" iyz="0" izz="0.001"/>
    </inertial>
  </link>
  <joint name="intake_joint" type="continuous">
    <parent link="base_link"/>
    <child link="intake_link"/>
    <origin xyz="0.2 0 0.1" rpy="0 1.5708 4.7124"/>
    <axis xyz="0 0 1"/>
  </joint>

  <!-- Spindexer (Rotating platform with dividers) -->
  <link name="spindexer_base_link">
    <visual>
      <geometry><cylinder length="0.01" radius="0.15"/></geometry>
      <material name="blue"/>
    </visual>
    <collision>
      <geometry><cylinder length="0.01" radius="0.15"/></geometry>
    </collision>
    <inertial>
      <mass value="0.5"/>
      <inertia ixx="0.005" ixy="0" ixz="0" iyy="0.005" iyz="0" izz="0.01"/>
    </inertial>
  </link>
  <joint name="spindexer_joint" type="continuous">
    <parent link="base_link"/>
    <child link="spindexer_base_link"/>
    <origin xyz="0 0 0.03" rpy="0 0 0"/>
    <axis xyz="0 0 1"/>
    <dynamics damping="0.1"/>
  </joint>

  <!-- Turret -->
  <link name="turret_link">
    <visual>
      <origin xyz="0 0 0" rpy="0 0 3.14159265359"/>
      <geometry><mesh filename="robotMeshes/shooter.stl" scale="1.0 1.0 1.0"/></geometry>
      <material name="red"/>
    </visual>
    <inertial>
      <mass value="1.0"/>
      <inertia ixx="0.01" iyy="0.01" izz="0.02432826"/>
    </inertial>
  </link>
  <joint name="turret_joint" type="continuous">
    <parent link="base_link"/>
    <child link="turret_link"/>
    <origin xyz="-0.039962 0 0.204265" rpy="0 0 0"/>
    <axis xyz="0 0 1"/>
    <dynamics damping="0.3"/>
  </joint>

  <!-- Flywheel -->
  <link name="flywheel_link">
    <visual>
      <geometry><cylinder length="0.02" radius="0.04"/></geometry>
      <material name="yellow"/>
    </visual>
    <collision>
      <geometry><cylinder length="0.02" radius="0.04"/></geometry>
    </collision>
    <inertial>
      <mass value="0.5"/>
      <inertia ixx="0.0005" ixy="0" ixz="0" iyy="0.0005" iyz="0" izz="0.0005"/>
    </inertial>
  </link>
  <joint name="flywheel_joint" type="continuous">
    <parent link="turret_link"/>
    <child link="flywheel_link"/>
    <origin xyz="0.05 0 0.05" rpy="0 1.5708 0"/>
    <axis xyz="0 0 1"/>
  </joint>

  <!-- Adjustable Hood -->
  <link name="hood_pivot">
     <inertial><mass value="0.01"/><inertia ixx="0.001" iyy="0.001" izz="0.001"/></inertial>
  </link>
  <joint name="hood_joint" type="revolute">
    <parent link="turret_link"/>
    <child link="hood_pivot"/>
    <origin xyz="-0.05 0 0.05" rpy="0 0 0"/>
    <axis xyz="0 1 0"/>
    <limit lower="0" upper="1.2" effort="5" velocity="5"/>
  </joint>


  <!-- Transfer Ramp (spindexer to turret feed) -->
  <link name="transfer_ramp">
    <visual>
      <geometry><box size="0.12 0.08 0.02"/></geometry>
      <material name="white"/>
    </visual>
    <inertial>
      <mass value="0.2"/>
      <inertia ixx="0.0002" iyy="0.0002" izz="0.002"/>
    </inertial>
  </link>
  <joint name="transfer_ramp_joint" type="fixed">
    <parent link="base_link"/>
    <child link="transfer_ramp"/>
    <origin xyz="-0.10 0 0.08" rpy="0 -0.45 0"/>
  </joint>

</robot>
